[2022-02-11 15:00:01,803] {taskinstance.py:1032} INFO - Dependencies all met for <TaskInstance: test_workflow_for_email.test_function scheduled__2022-02-11T14:00:00+00:00 [queued]>
[2022-02-11 15:00:01,836] {taskinstance.py:1032} INFO - Dependencies all met for <TaskInstance: test_workflow_for_email.test_function scheduled__2022-02-11T14:00:00+00:00 [queued]>
[2022-02-11 15:00:01,839] {taskinstance.py:1238} INFO - 
--------------------------------------------------------------------------------
[2022-02-11 15:00:01,841] {taskinstance.py:1239} INFO - Starting attempt 1 of 1
[2022-02-11 15:00:01,844] {taskinstance.py:1240} INFO - 
--------------------------------------------------------------------------------
[2022-02-11 15:00:01,877] {taskinstance.py:1259} INFO - Executing <Task(PythonOperator): test_function> on 2022-02-11 14:00:00+00:00
[2022-02-11 15:00:01,889] {standard_task_runner.py:52} INFO - Started process 1901 to run task
[2022-02-11 15:00:01,899] {standard_task_runner.py:76} INFO - Running: ['***', 'tasks', 'run', 'test_workflow_for_email', 'test_function', 'scheduled__2022-02-11T14:00:00+00:00', '--job-id', '94', '--raw', '--subdir', 'DAGS_FOLDER/test_workflow_for_email.py', '--cfg-path', '/tmp/tmpnblegghs', '--error-file', '/tmp/tmpm5j4g9sa']
[2022-02-11 15:00:01,902] {standard_task_runner.py:77} INFO - Job 94: Subtask test_function
[2022-02-11 15:00:02,224] {logging_mixin.py:109} INFO - Running <TaskInstance: test_workflow_for_email.test_function scheduled__2022-02-11T14:00:00+00:00 [running]> on host c762f4aacf84
[2022-02-11 15:00:02,455] {taskinstance.py:1426} INFO - Exporting the following env vars:
AIRFLOW_CTX_DAG_EMAIL=dhapathekabolchi@gmail.com
AIRFLOW_CTX_DAG_OWNER=arflow
AIRFLOW_CTX_DAG_ID=test_workflow_for_email
AIRFLOW_CTX_TASK_ID=test_function
AIRFLOW_CTX_EXECUTION_DATE=2022-02-11T14:00:00+00:00
AIRFLOW_CTX_DAG_RUN_ID=scheduled__2022-02-11T14:00:00+00:00
[2022-02-11 15:00:02,462] {taskinstance.py:1700} ERROR - Task failed with exception
Traceback (most recent call last):
  File "/home/airflow/.local/lib/python3.7/site-packages/airflow/models/taskinstance.py", line 1329, in _run_raw_task
    self._execute_task_with_callbacks(context)
  File "/home/airflow/.local/lib/python3.7/site-packages/airflow/models/taskinstance.py", line 1455, in _execute_task_with_callbacks
    result = self._execute_task(context, self.task)
  File "/home/airflow/.local/lib/python3.7/site-packages/airflow/models/taskinstance.py", line 1511, in _execute_task
    result = execute_callable(context=context)
  File "/home/airflow/.local/lib/python3.7/site-packages/airflow/operators/python.py", line 174, in execute
    return_value = self.execute_callable()
  File "/home/airflow/.local/lib/python3.7/site-packages/airflow/operators/python.py", line 185, in execute_callable
    return self.python_callable(*self.op_args, **self.op_kwargs)
  File "/opt/airflow/dags/test_workflow_for_email.py", line 9, in test_function
    with io.open("/opt/airflow/output_files1/tutorial2.txt","w",encoding="utf-8")as f1:
FileNotFoundError: [Errno 2] No such file or directory: '/opt/airflow/output_files1/tutorial2.txt'
[2022-02-11 15:00:02,502] {taskinstance.py:1277} INFO - Marking task as FAILED. dag_id=test_workflow_for_email, task_id=test_function, execution_date=20220211T140000, start_date=20220211T150001, end_date=20220211T150002
[2022-02-11 15:00:02,582] {warnings.py:110} WARNING - /home/***/.local/lib/python3.7/site-packages/***/utils/context.py:152: AirflowContextDeprecationWarning: Accessing 'execution_date' from the template is deprecated and will be removed in a future version. Please use 'data_interval_start' or 'logical_date' instead.
  warnings.warn(_create_deprecation_warning(key, self._deprecation_replacements[key]))

[2022-02-11 15:00:02,584] {warnings.py:110} WARNING - /home/***/.local/lib/python3.7/site-packages/***/utils/context.py:152: AirflowContextDeprecationWarning: Accessing 'next_ds' from the template is deprecated and will be removed in a future version. Please use '{{ data_interval_end | ds }}' instead.
  warnings.warn(_create_deprecation_warning(key, self._deprecation_replacements[key]))

[2022-02-11 15:00:02,588] {warnings.py:110} WARNING - /home/***/.local/lib/python3.7/site-packages/***/utils/context.py:152: AirflowContextDeprecationWarning: Accessing 'next_ds_nodash' from the template is deprecated and will be removed in a future version. Please use '{{ data_interval_end | ds_nodash }}' instead.
  warnings.warn(_create_deprecation_warning(key, self._deprecation_replacements[key]))

[2022-02-11 15:00:02,590] {warnings.py:110} WARNING - /home/***/.local/lib/python3.7/site-packages/***/utils/context.py:152: AirflowContextDeprecationWarning: Accessing 'next_execution_date' from the template is deprecated and will be removed in a future version. Please use 'data_interval_end' instead.
  warnings.warn(_create_deprecation_warning(key, self._deprecation_replacements[key]))

[2022-02-11 15:00:02,592] {warnings.py:110} WARNING - /home/***/.local/lib/python3.7/site-packages/***/utils/context.py:152: AirflowContextDeprecationWarning: Accessing 'prev_ds' from the template is deprecated and will be removed in a future version.
  warnings.warn(_create_deprecation_warning(key, self._deprecation_replacements[key]))

[2022-02-11 15:00:02,594] {warnings.py:110} WARNING - /home/***/.local/lib/python3.7/site-packages/***/utils/context.py:152: AirflowContextDeprecationWarning: Accessing 'prev_ds_nodash' from the template is deprecated and will be removed in a future version.
  warnings.warn(_create_deprecation_warning(key, self._deprecation_replacements[key]))

[2022-02-11 15:00:02,596] {warnings.py:110} WARNING - /home/***/.local/lib/python3.7/site-packages/***/utils/context.py:152: AirflowContextDeprecationWarning: Accessing 'prev_execution_date' from the template is deprecated and will be removed in a future version.
  warnings.warn(_create_deprecation_warning(key, self._deprecation_replacements[key]))

[2022-02-11 15:00:02,601] {warnings.py:110} WARNING - /home/***/.local/lib/python3.7/site-packages/***/utils/context.py:152: AirflowContextDeprecationWarning: Accessing 'prev_execution_date_success' from the template is deprecated and will be removed in a future version. Please use 'prev_data_interval_start_success' instead.
  warnings.warn(_create_deprecation_warning(key, self._deprecation_replacements[key]))

[2022-02-11 15:00:02,605] {warnings.py:110} WARNING - /home/***/.local/lib/python3.7/site-packages/***/utils/context.py:152: AirflowContextDeprecationWarning: Accessing 'tomorrow_ds' from the template is deprecated and will be removed in a future version.
  warnings.warn(_create_deprecation_warning(key, self._deprecation_replacements[key]))

[2022-02-11 15:00:02,607] {warnings.py:110} WARNING - /home/***/.local/lib/python3.7/site-packages/***/utils/context.py:152: AirflowContextDeprecationWarning: Accessing 'tomorrow_ds_nodash' from the template is deprecated and will be removed in a future version.
  warnings.warn(_create_deprecation_warning(key, self._deprecation_replacements[key]))

[2022-02-11 15:00:02,609] {warnings.py:110} WARNING - /home/***/.local/lib/python3.7/site-packages/***/utils/context.py:152: AirflowContextDeprecationWarning: Accessing 'yesterday_ds' from the template is deprecated and will be removed in a future version.
  warnings.warn(_create_deprecation_warning(key, self._deprecation_replacements[key]))

[2022-02-11 15:00:02,611] {warnings.py:110} WARNING - /home/***/.local/lib/python3.7/site-packages/***/utils/context.py:152: AirflowContextDeprecationWarning: Accessing 'yesterday_ds_nodash' from the template is deprecated and will be removed in a future version.
  warnings.warn(_create_deprecation_warning(key, self._deprecation_replacements[key]))

[2022-02-11 15:00:02,674] {warnings.py:110} WARNING - /home/***/.local/lib/python3.7/site-packages/***/utils/email.py:102: PendingDeprecationWarning: Fetching SMTP credentials from configuration variables will be deprecated in a future release. Please set credentials using a connection instead.
  send_mime_email(e_from=smtp_mail_from, e_to=recipients, mime_msg=msg, conn_id=conn_id, dryrun=dryrun)

[2022-02-11 15:00:02,679] {email.py:208} INFO - Email alerting: attempt 1
[2022-02-11 15:00:04,505] {email.py:220} INFO - Sent an alert email to ['dhapathekabolchi@gmail.com']
[2022-02-11 15:00:07,040] {standard_task_runner.py:92} ERROR - Failed to execute job 94 for task test_function
Traceback (most recent call last):
  File "/home/airflow/.local/lib/python3.7/site-packages/airflow/task/task_runner/standard_task_runner.py", line 85, in _start_by_fork
    args.func(args, dag=self.dag)
  File "/home/airflow/.local/lib/python3.7/site-packages/airflow/cli/cli_parser.py", line 48, in command
    return func(*args, **kwargs)
  File "/home/airflow/.local/lib/python3.7/site-packages/airflow/utils/cli.py", line 92, in wrapper
    return f(*args, **kwargs)
  File "/home/airflow/.local/lib/python3.7/site-packages/airflow/cli/commands/task_command.py", line 298, in task_run
    _run_task_by_selected_method(args, dag, ti)
  File "/home/airflow/.local/lib/python3.7/site-packages/airflow/cli/commands/task_command.py", line 107, in _run_task_by_selected_method
    _run_raw_task(args, ti)
  File "/home/airflow/.local/lib/python3.7/site-packages/airflow/cli/commands/task_command.py", line 184, in _run_raw_task
    error_file=args.error_file,
  File "/home/airflow/.local/lib/python3.7/site-packages/airflow/utils/session.py", line 70, in wrapper
    return func(*args, session=session, **kwargs)
  File "/home/airflow/.local/lib/python3.7/site-packages/airflow/models/taskinstance.py", line 1329, in _run_raw_task
    self._execute_task_with_callbacks(context)
  File "/home/airflow/.local/lib/python3.7/site-packages/airflow/models/taskinstance.py", line 1455, in _execute_task_with_callbacks
    result = self._execute_task(context, self.task)
  File "/home/airflow/.local/lib/python3.7/site-packages/airflow/models/taskinstance.py", line 1511, in _execute_task
    result = execute_callable(context=context)
  File "/home/airflow/.local/lib/python3.7/site-packages/airflow/operators/python.py", line 174, in execute
    return_value = self.execute_callable()
  File "/home/airflow/.local/lib/python3.7/site-packages/airflow/operators/python.py", line 185, in execute_callable
    return self.python_callable(*self.op_args, **self.op_kwargs)
  File "/opt/airflow/dags/test_workflow_for_email.py", line 9, in test_function
    with io.open("/opt/airflow/output_files1/tutorial2.txt","w",encoding="utf-8")as f1:
FileNotFoundError: [Errno 2] No such file or directory: '/opt/airflow/output_files1/tutorial2.txt'
[2022-02-11 15:00:07,063] {local_task_job.py:212} WARNING - State of this instance has been externally set to failed. Terminating instance.
[2022-02-11 15:00:07,073] {process_utils.py:124} INFO - Sending Signals.SIGTERM to group 1901. PIDs of all processes in the group: [1901]
[2022-02-11 15:00:07,078] {process_utils.py:75} INFO - Sending the signal Signals.SIGTERM to group 1901
[2022-02-11 15:00:07,082] {process_utils.py:70} INFO - Process psutil.Process(pid=1901, status='terminated', exitcode=1, started='15:00:01') (1901) terminated with exit code 1
