[2022-02-13 04:32:04,333] {taskinstance.py:1032} INFO - Dependencies all met for <TaskInstance: test_neo4j.run_neo4j_query manual__2022-02-13T04:32:02.059610+00:00 [queued]>
[2022-02-13 04:32:04,366] {taskinstance.py:1032} INFO - Dependencies all met for <TaskInstance: test_neo4j.run_neo4j_query manual__2022-02-13T04:32:02.059610+00:00 [queued]>
[2022-02-13 04:32:04,371] {taskinstance.py:1238} INFO - 
--------------------------------------------------------------------------------
[2022-02-13 04:32:04,390] {taskinstance.py:1239} INFO - Starting attempt 1 of 1
[2022-02-13 04:32:04,396] {taskinstance.py:1240} INFO - 
--------------------------------------------------------------------------------
[2022-02-13 04:32:04,471] {taskinstance.py:1259} INFO - Executing <Task(Neo4jOperator): run_neo4j_query> on 2022-02-13 04:32:02.059610+00:00
[2022-02-13 04:32:04,501] {standard_task_runner.py:52} INFO - Started process 120 to run task
[2022-02-13 04:32:04,518] {standard_task_runner.py:76} INFO - Running: ['***', 'tasks', 'run', 'test_neo4j', 'run_neo4j_query', 'manual__2022-02-13T04:32:02.059610+00:00', '--job-id', '143', '--raw', '--subdir', 'DAGS_FOLDER/test_neo4j.py', '--cfg-path', '/tmp/tmps0_gk6mn', '--error-file', '/tmp/tmpxwawdwmb']
[2022-02-13 04:32:04,526] {standard_task_runner.py:77} INFO - Job 143: Subtask run_neo4j_query
[2022-02-13 04:32:04,756] {logging_mixin.py:109} INFO - Running <TaskInstance: test_neo4j.run_neo4j_query manual__2022-02-13T04:32:02.059610+00:00 [running]> on host 0c4036010199
[2022-02-13 04:32:05,027] {taskinstance.py:1426} INFO - Exporting the following env vars:
AIRFLOW_CTX_DAG_OWNER=***
AIRFLOW_CTX_DAG_ID=test_neo4j
AIRFLOW_CTX_TASK_ID=run_neo4j_query
AIRFLOW_CTX_EXECUTION_DATE=2022-02-13T04:32:02.059610+00:00
AIRFLOW_CTX_DAG_RUN_ID=manual__2022-02-13T04:32:02.059610+00:00
[2022-02-13 04:32:05,036] {neo4j.py:58} INFO - Executing: MATCH (tom {name: "Tom Hanks", date: "2022-02-13"}) RETURN tom
[2022-02-13 04:32:05,099] {taskinstance.py:1700} ERROR - Task failed with exception
Traceback (most recent call last):
  File "/home/airflow/.local/lib/python3.7/site-packages/airflow/models/taskinstance.py", line 1329, in _run_raw_task
    self._execute_task_with_callbacks(context)
  File "/home/airflow/.local/lib/python3.7/site-packages/airflow/models/taskinstance.py", line 1455, in _execute_task_with_callbacks
    result = self._execute_task(context, self.task)
  File "/home/airflow/.local/lib/python3.7/site-packages/airflow/models/taskinstance.py", line 1511, in _execute_task
    result = execute_callable(context=context)
  File "/home/airflow/.local/lib/python3.7/site-packages/airflow/providers/neo4j/operators/neo4j.py", line 60, in execute
    hook.run(self.sql)
  File "/home/airflow/.local/lib/python3.7/site-packages/airflow/providers/neo4j/hooks/neo4j.py", line 110, in run
    driver = self.get_conn()
  File "/home/airflow/.local/lib/python3.7/site-packages/airflow/providers/neo4j/hooks/neo4j.py", line 56, in get_conn
    self.connection = self.get_connection(self.neo4j_conn_id)
  File "/home/airflow/.local/lib/python3.7/site-packages/airflow/hooks/base.py", line 68, in get_connection
    conn = Connection.get_connection_from_secrets(conn_id)
  File "/home/airflow/.local/lib/python3.7/site-packages/airflow/models/connection.py", line 410, in get_connection_from_secrets
    raise AirflowNotFoundException(f"The conn_id `{conn_id}` isn't defined")
airflow.exceptions.AirflowNotFoundException: The conn_id `neo4j_default` isn't defined
[2022-02-13 04:32:05,120] {taskinstance.py:1277} INFO - Marking task as FAILED. dag_id=test_neo4j, task_id=run_neo4j_query, execution_date=20220213T043202, start_date=20220213T043204, end_date=20220213T043205
[2022-02-13 04:32:05,161] {standard_task_runner.py:92} ERROR - Failed to execute job 143 for task run_neo4j_query
Traceback (most recent call last):
  File "/home/airflow/.local/lib/python3.7/site-packages/airflow/task/task_runner/standard_task_runner.py", line 85, in _start_by_fork
    args.func(args, dag=self.dag)
  File "/home/airflow/.local/lib/python3.7/site-packages/airflow/cli/cli_parser.py", line 48, in command
    return func(*args, **kwargs)
  File "/home/airflow/.local/lib/python3.7/site-packages/airflow/utils/cli.py", line 92, in wrapper
    return f(*args, **kwargs)
  File "/home/airflow/.local/lib/python3.7/site-packages/airflow/cli/commands/task_command.py", line 298, in task_run
    _run_task_by_selected_method(args, dag, ti)
  File "/home/airflow/.local/lib/python3.7/site-packages/airflow/cli/commands/task_command.py", line 107, in _run_task_by_selected_method
    _run_raw_task(args, ti)
  File "/home/airflow/.local/lib/python3.7/site-packages/airflow/cli/commands/task_command.py", line 184, in _run_raw_task
    error_file=args.error_file,
  File "/home/airflow/.local/lib/python3.7/site-packages/airflow/utils/session.py", line 70, in wrapper
    return func(*args, session=session, **kwargs)
  File "/home/airflow/.local/lib/python3.7/site-packages/airflow/models/taskinstance.py", line 1329, in _run_raw_task
    self._execute_task_with_callbacks(context)
  File "/home/airflow/.local/lib/python3.7/site-packages/airflow/models/taskinstance.py", line 1455, in _execute_task_with_callbacks
    result = self._execute_task(context, self.task)
  File "/home/airflow/.local/lib/python3.7/site-packages/airflow/models/taskinstance.py", line 1511, in _execute_task
    result = execute_callable(context=context)
  File "/home/airflow/.local/lib/python3.7/site-packages/airflow/providers/neo4j/operators/neo4j.py", line 60, in execute
    hook.run(self.sql)
  File "/home/airflow/.local/lib/python3.7/site-packages/airflow/providers/neo4j/hooks/neo4j.py", line 110, in run
    driver = self.get_conn()
  File "/home/airflow/.local/lib/python3.7/site-packages/airflow/providers/neo4j/hooks/neo4j.py", line 56, in get_conn
    self.connection = self.get_connection(self.neo4j_conn_id)
  File "/home/airflow/.local/lib/python3.7/site-packages/airflow/hooks/base.py", line 68, in get_connection
    conn = Connection.get_connection_from_secrets(conn_id)
  File "/home/airflow/.local/lib/python3.7/site-packages/airflow/models/connection.py", line 410, in get_connection_from_secrets
    raise AirflowNotFoundException(f"The conn_id `{conn_id}` isn't defined")
airflow.exceptions.AirflowNotFoundException: The conn_id `neo4j_default` isn't defined
[2022-02-13 04:32:05,219] {local_task_job.py:154} INFO - Task exited with return code 1
[2022-02-13 04:32:05,320] {local_task_job.py:264} INFO - 0 downstream tasks scheduled from follow-on schedule check
