[2022-02-13 03:43:06,877] {taskinstance.py:1032} INFO - Dependencies all met for <TaskInstance: test_workflow_for_email.test_function scheduled__2022-02-12T00:00:00+00:00 [queued]>
[2022-02-13 03:43:07,184] {taskinstance.py:1032} INFO - Dependencies all met for <TaskInstance: test_workflow_for_email.test_function scheduled__2022-02-12T00:00:00+00:00 [queued]>
[2022-02-13 03:43:07,187] {taskinstance.py:1238} INFO - 
--------------------------------------------------------------------------------
[2022-02-13 03:43:07,202] {taskinstance.py:1239} INFO - Starting attempt 1 of 1
[2022-02-13 03:43:07,210] {taskinstance.py:1240} INFO - 
--------------------------------------------------------------------------------
[2022-02-13 03:43:07,426] {taskinstance.py:1259} INFO - Executing <Task(PythonOperator): test_function> on 2022-02-12 00:00:00+00:00
[2022-02-13 03:43:07,472] {standard_task_runner.py:52} INFO - Started process 118 to run task
[2022-02-13 03:43:07,525] {standard_task_runner.py:76} INFO - Running: ['***', 'tasks', 'run', 'test_workflow_for_email', 'test_function', 'scheduled__2022-02-12T00:00:00+00:00', '--job-id', '114', '--raw', '--subdir', 'DAGS_FOLDER/test_workflow_for_email.py', '--cfg-path', '/tmp/tmpk43s5zsb', '--error-file', '/tmp/tmpvupysgb6']
[2022-02-13 03:43:07,540] {standard_task_runner.py:77} INFO - Job 114: Subtask test_function
[2022-02-13 03:43:08,334] {logging_mixin.py:109} INFO - Running <TaskInstance: test_workflow_for_email.test_function scheduled__2022-02-12T00:00:00+00:00 [running]> on host c762f4aacf84
[2022-02-13 03:43:10,007] {taskinstance.py:1426} INFO - Exporting the following env vars:
AIRFLOW_CTX_DAG_EMAIL=dhapathekabolchi@gmail.com
AIRFLOW_CTX_DAG_OWNER=arflow
AIRFLOW_CTX_DAG_ID=test_workflow_for_email
AIRFLOW_CTX_TASK_ID=test_function
AIRFLOW_CTX_EXECUTION_DATE=2022-02-12T00:00:00+00:00
AIRFLOW_CTX_DAG_RUN_ID=scheduled__2022-02-12T00:00:00+00:00
[2022-02-13 03:43:10,098] {taskinstance.py:1700} ERROR - Task failed with exception
Traceback (most recent call last):
  File "/home/airflow/.local/lib/python3.7/site-packages/airflow/models/taskinstance.py", line 1329, in _run_raw_task
    self._execute_task_with_callbacks(context)
  File "/home/airflow/.local/lib/python3.7/site-packages/airflow/models/taskinstance.py", line 1455, in _execute_task_with_callbacks
    result = self._execute_task(context, self.task)
  File "/home/airflow/.local/lib/python3.7/site-packages/airflow/models/taskinstance.py", line 1511, in _execute_task
    result = execute_callable(context=context)
  File "/home/airflow/.local/lib/python3.7/site-packages/airflow/operators/python.py", line 174, in execute
    return_value = self.execute_callable()
  File "/home/airflow/.local/lib/python3.7/site-packages/airflow/operators/python.py", line 185, in execute_callable
    return self.python_callable(*self.op_args, **self.op_kwargs)
  File "/opt/airflow/dags/test_workflow_for_email.py", line 9, in test_function
    with io.open("/opt/airflow/output_files1/tutorial2.txt","w",encoding="utf-8")as f1:
FileNotFoundError: [Errno 2] No such file or directory: '/opt/airflow/output_files1/tutorial2.txt'
[2022-02-13 03:43:10,377] {taskinstance.py:1277} INFO - Marking task as FAILED. dag_id=test_workflow_for_email, task_id=test_function, execution_date=20220212T000000, start_date=20220213T034306, end_date=20220213T034310
[2022-02-13 03:43:10,683] {warnings.py:110} WARNING - /home/***/.local/lib/python3.7/site-packages/***/utils/context.py:152: AirflowContextDeprecationWarning: Accessing 'execution_date' from the template is deprecated and will be removed in a future version. Please use 'data_interval_start' or 'logical_date' instead.
  warnings.warn(_create_deprecation_warning(key, self._deprecation_replacements[key]))

[2022-02-13 03:43:10,685] {warnings.py:110} WARNING - /home/***/.local/lib/python3.7/site-packages/***/utils/context.py:152: AirflowContextDeprecationWarning: Accessing 'next_ds' from the template is deprecated and will be removed in a future version. Please use '{{ data_interval_end | ds }}' instead.
  warnings.warn(_create_deprecation_warning(key, self._deprecation_replacements[key]))

[2022-02-13 03:43:10,688] {warnings.py:110} WARNING - /home/***/.local/lib/python3.7/site-packages/***/utils/context.py:152: AirflowContextDeprecationWarning: Accessing 'next_ds_nodash' from the template is deprecated and will be removed in a future version. Please use '{{ data_interval_end | ds_nodash }}' instead.
  warnings.warn(_create_deprecation_warning(key, self._deprecation_replacements[key]))

[2022-02-13 03:43:10,689] {warnings.py:110} WARNING - /home/***/.local/lib/python3.7/site-packages/***/utils/context.py:152: AirflowContextDeprecationWarning: Accessing 'next_execution_date' from the template is deprecated and will be removed in a future version. Please use 'data_interval_end' instead.
  warnings.warn(_create_deprecation_warning(key, self._deprecation_replacements[key]))

[2022-02-13 03:43:10,690] {warnings.py:110} WARNING - /home/***/.local/lib/python3.7/site-packages/***/utils/context.py:152: AirflowContextDeprecationWarning: Accessing 'prev_ds' from the template is deprecated and will be removed in a future version.
  warnings.warn(_create_deprecation_warning(key, self._deprecation_replacements[key]))

[2022-02-13 03:43:10,691] {warnings.py:110} WARNING - /home/***/.local/lib/python3.7/site-packages/***/utils/context.py:152: AirflowContextDeprecationWarning: Accessing 'prev_ds_nodash' from the template is deprecated and will be removed in a future version.
  warnings.warn(_create_deprecation_warning(key, self._deprecation_replacements[key]))

[2022-02-13 03:43:10,693] {warnings.py:110} WARNING - /home/***/.local/lib/python3.7/site-packages/***/utils/context.py:152: AirflowContextDeprecationWarning: Accessing 'prev_execution_date' from the template is deprecated and will be removed in a future version.
  warnings.warn(_create_deprecation_warning(key, self._deprecation_replacements[key]))

[2022-02-13 03:43:10,694] {warnings.py:110} WARNING - /home/***/.local/lib/python3.7/site-packages/***/utils/context.py:152: AirflowContextDeprecationWarning: Accessing 'prev_execution_date_success' from the template is deprecated and will be removed in a future version. Please use 'prev_data_interval_start_success' instead.
  warnings.warn(_create_deprecation_warning(key, self._deprecation_replacements[key]))

[2022-02-13 03:43:10,697] {warnings.py:110} WARNING - /home/***/.local/lib/python3.7/site-packages/***/utils/context.py:152: AirflowContextDeprecationWarning: Accessing 'tomorrow_ds' from the template is deprecated and will be removed in a future version.
  warnings.warn(_create_deprecation_warning(key, self._deprecation_replacements[key]))

[2022-02-13 03:43:10,698] {warnings.py:110} WARNING - /home/***/.local/lib/python3.7/site-packages/***/utils/context.py:152: AirflowContextDeprecationWarning: Accessing 'tomorrow_ds_nodash' from the template is deprecated and will be removed in a future version.
  warnings.warn(_create_deprecation_warning(key, self._deprecation_replacements[key]))

[2022-02-13 03:43:10,699] {warnings.py:110} WARNING - /home/***/.local/lib/python3.7/site-packages/***/utils/context.py:152: AirflowContextDeprecationWarning: Accessing 'yesterday_ds' from the template is deprecated and will be removed in a future version.
  warnings.warn(_create_deprecation_warning(key, self._deprecation_replacements[key]))

[2022-02-13 03:43:10,701] {warnings.py:110} WARNING - /home/***/.local/lib/python3.7/site-packages/***/utils/context.py:152: AirflowContextDeprecationWarning: Accessing 'yesterday_ds_nodash' from the template is deprecated and will be removed in a future version.
  warnings.warn(_create_deprecation_warning(key, self._deprecation_replacements[key]))

[2022-02-13 03:43:10,877] {warnings.py:110} WARNING - /home/***/.local/lib/python3.7/site-packages/***/utils/email.py:102: PendingDeprecationWarning: Fetching SMTP credentials from configuration variables will be deprecated in a future release. Please set credentials using a connection instead.
  send_mime_email(e_from=smtp_mail_from, e_to=recipients, mime_msg=msg, conn_id=conn_id, dryrun=dryrun)

[2022-02-13 03:43:10,881] {email.py:208} INFO - Email alerting: attempt 1
[2022-02-13 03:43:13,271] {email.py:208} INFO - Email alerting: attempt 1
[2022-02-13 03:43:15,280] {taskinstance.py:1751} ERROR - Failed to send email to: ['dhapathekabolchi@gmail.com']
Traceback (most recent call last):
  File "/home/airflow/.local/lib/python3.7/site-packages/airflow/models/taskinstance.py", line 1329, in _run_raw_task
    self._execute_task_with_callbacks(context)
  File "/home/airflow/.local/lib/python3.7/site-packages/airflow/models/taskinstance.py", line 1455, in _execute_task_with_callbacks
    result = self._execute_task(context, self.task)
  File "/home/airflow/.local/lib/python3.7/site-packages/airflow/models/taskinstance.py", line 1511, in _execute_task
    result = execute_callable(context=context)
  File "/home/airflow/.local/lib/python3.7/site-packages/airflow/operators/python.py", line 174, in execute
    return_value = self.execute_callable()
  File "/home/airflow/.local/lib/python3.7/site-packages/airflow/operators/python.py", line 185, in execute_callable
    return self.python_callable(*self.op_args, **self.op_kwargs)
  File "/opt/airflow/dags/test_workflow_for_email.py", line 9, in test_function
    with io.open("/opt/airflow/output_files1/tutorial2.txt","w",encoding="utf-8")as f1:
FileNotFoundError: [Errno 2] No such file or directory: '/opt/airflow/output_files1/tutorial2.txt'

During handling of the above exception, another exception occurred:

Traceback (most recent call last):
  File "/home/airflow/.local/lib/python3.7/site-packages/airflow/models/taskinstance.py", line 2093, in email_alert
    send_email(self.task.email, subject, html_content)
  File "/home/airflow/.local/lib/python3.7/site-packages/airflow/utils/email.py", line 66, in send_email
    **kwargs,
  File "/home/airflow/.local/lib/python3.7/site-packages/airflow/utils/email.py", line 102, in send_email_smtp
    send_mime_email(e_from=smtp_mail_from, e_to=recipients, mime_msg=msg, conn_id=conn_id, dryrun=dryrun)
  File "/home/airflow/.local/lib/python3.7/site-packages/airflow/utils/email.py", line 219, in send_mime_email
    conn.login(smtp_user, smtp_password)
  File "/usr/local/lib/python3.7/smtplib.py", line 735, in login
    raise last_exception
  File "/usr/local/lib/python3.7/smtplib.py", line 726, in login
    initial_response_ok=initial_response_ok)
  File "/usr/local/lib/python3.7/smtplib.py", line 647, in auth
    raise SMTPAuthenticationError(code, resp)
smtplib.SMTPAuthenticationError: (535, b'5.7.8 Username and Password not accepted. Learn more at\n5.7.8  https://support.google.com/mail/?p=BadCredentials kx5sm9421366pjb.16 - gsmtp')

During handling of the above exception, another exception occurred:

Traceback (most recent call last):
  File "/home/airflow/.local/lib/python3.7/site-packages/airflow/models/taskinstance.py", line 1749, in handle_failure
    self.email_alert(error)
  File "/home/airflow/.local/lib/python3.7/site-packages/airflow/models/taskinstance.py", line 2095, in email_alert
    send_email(self.task.email, subject, html_content_err)
  File "/home/airflow/.local/lib/python3.7/site-packages/airflow/utils/email.py", line 66, in send_email
    **kwargs,
  File "/home/airflow/.local/lib/python3.7/site-packages/airflow/utils/email.py", line 102, in send_email_smtp
    send_mime_email(e_from=smtp_mail_from, e_to=recipients, mime_msg=msg, conn_id=conn_id, dryrun=dryrun)
  File "/home/airflow/.local/lib/python3.7/site-packages/airflow/utils/email.py", line 219, in send_mime_email
    conn.login(smtp_user, smtp_password)
  File "/usr/local/lib/python3.7/smtplib.py", line 735, in login
    raise last_exception
  File "/usr/local/lib/python3.7/smtplib.py", line 726, in login
    initial_response_ok=initial_response_ok)
  File "/usr/local/lib/python3.7/smtplib.py", line 647, in auth
    raise SMTPAuthenticationError(code, resp)
smtplib.SMTPAuthenticationError: (535, b'5.7.8 Username and Password not accepted. Learn more at\n5.7.8  https://support.google.com/mail/?p=BadCredentials mu13sm10057562pjb.28 - gsmtp')
[2022-02-13 03:43:16,157] {standard_task_runner.py:92} ERROR - Failed to execute job 114 for task test_function
Traceback (most recent call last):
  File "/home/airflow/.local/lib/python3.7/site-packages/airflow/task/task_runner/standard_task_runner.py", line 85, in _start_by_fork
    args.func(args, dag=self.dag)
  File "/home/airflow/.local/lib/python3.7/site-packages/airflow/cli/cli_parser.py", line 48, in command
    return func(*args, **kwargs)
  File "/home/airflow/.local/lib/python3.7/site-packages/airflow/utils/cli.py", line 92, in wrapper
    return f(*args, **kwargs)
  File "/home/airflow/.local/lib/python3.7/site-packages/airflow/cli/commands/task_command.py", line 298, in task_run
    _run_task_by_selected_method(args, dag, ti)
  File "/home/airflow/.local/lib/python3.7/site-packages/airflow/cli/commands/task_command.py", line 107, in _run_task_by_selected_method
    _run_raw_task(args, ti)
  File "/home/airflow/.local/lib/python3.7/site-packages/airflow/cli/commands/task_command.py", line 184, in _run_raw_task
    error_file=args.error_file,
  File "/home/airflow/.local/lib/python3.7/site-packages/airflow/utils/session.py", line 70, in wrapper
    return func(*args, session=session, **kwargs)
  File "/home/airflow/.local/lib/python3.7/site-packages/airflow/models/taskinstance.py", line 1329, in _run_raw_task
    self._execute_task_with_callbacks(context)
  File "/home/airflow/.local/lib/python3.7/site-packages/airflow/models/taskinstance.py", line 1455, in _execute_task_with_callbacks
    result = self._execute_task(context, self.task)
  File "/home/airflow/.local/lib/python3.7/site-packages/airflow/models/taskinstance.py", line 1511, in _execute_task
    result = execute_callable(context=context)
  File "/home/airflow/.local/lib/python3.7/site-packages/airflow/operators/python.py", line 174, in execute
    return_value = self.execute_callable()
  File "/home/airflow/.local/lib/python3.7/site-packages/airflow/operators/python.py", line 185, in execute_callable
    return self.python_callable(*self.op_args, **self.op_kwargs)
  File "/opt/airflow/dags/test_workflow_for_email.py", line 9, in test_function
    with io.open("/opt/airflow/output_files1/tutorial2.txt","w",encoding="utf-8")as f1:
FileNotFoundError: [Errno 2] No such file or directory: '/opt/airflow/output_files1/tutorial2.txt'
[2022-02-13 03:43:16,205] {local_task_job.py:154} INFO - Task exited with return code 1
[2022-02-13 03:43:16,569] {local_task_job.py:264} INFO - 0 downstream tasks scheduled from follow-on schedule check
